2020-02-17 21:51:33,573 ERROR: Exception on / [GET] [in c:\users\ssant\drive\github\dashboard\venv_dashboard\lib\site-packages\flask\app.py:1761]
Traceback (most recent call last):
  File "c:\users\ssant\drive\github\dashboard\venv_dashboard\lib\site-packages\flask\app.py", line 2292, in wsgi_app
    response = self.full_dispatch_request()
  File "c:\users\ssant\drive\github\dashboard\venv_dashboard\lib\site-packages\flask\app.py", line 1815, in full_dispatch_request
    rv = self.handle_user_exception(e)
  File "c:\users\ssant\drive\github\dashboard\venv_dashboard\lib\site-packages\flask\app.py", line 1718, in handle_user_exception
    reraise(exc_type, exc_value, tb)
  File "c:\users\ssant\drive\github\dashboard\venv_dashboard\lib\site-packages\flask\_compat.py", line 35, in reraise
    raise value
  File "c:\users\ssant\drive\github\dashboard\venv_dashboard\lib\site-packages\flask\app.py", line 1813, in full_dispatch_request
    rv = self.dispatch_request()
  File "c:\users\ssant\drive\github\dashboard\venv_dashboard\lib\site-packages\flask\app.py", line 1799, in dispatch_request
    return self.view_functions[rule.endpoint](**req.view_args)
  File "c:\users\ssant\drive\github\dashboard\venv_dashboard\lib\site-packages\flask_login\utils.py", line 228, in decorated_view
    return func(*args, **kwargs)
  File "C:\Users\ssant\drive\github\dashboard\app\main\routes.py", line 41, in index
    prev_url=prev_url)
  File "c:\users\ssant\drive\github\dashboard\venv_dashboard\lib\site-packages\flask\templating.py", line 135, in render_template
    context, ctx.app)
  File "c:\users\ssant\drive\github\dashboard\venv_dashboard\lib\site-packages\flask\templating.py", line 117, in _render
    rv = template.render(context)
  File "c:\users\ssant\drive\github\dashboard\venv_dashboard\lib\site-packages\jinja2\asyncsupport.py", line 76, in render
    return original_render(self, *args, **kwargs)
  File "c:\users\ssant\drive\github\dashboard\venv_dashboard\lib\site-packages\jinja2\environment.py", line 1008, in render
    return self.environment.handle_exception(exc_info, True)
  File "c:\users\ssant\drive\github\dashboard\venv_dashboard\lib\site-packages\jinja2\environment.py", line 780, in handle_exception
    reraise(exc_type, exc_value, tb)
  File "c:\users\ssant\drive\github\dashboard\venv_dashboard\lib\site-packages\jinja2\_compat.py", line 37, in reraise
    raise value.with_traceback(tb)
  File "C:\Users\ssant\drive\github\dashboard\app\templates\index.html", line 2, in top-level template code
    {% import 'bootstrap/wtf.html' as wtf %}
  File "C:\Users\ssant\drive\github\dashboard\app\templates\base.html", line 1, in top-level template code
    {% extends 'bootstrap/base.html' %}
  File "c:\users\ssant\drive\github\dashboard\venv_dashboard\lib\site-packages\flask_bootstrap\templates\bootstrap\base.html", line 1, in top-level template code
    {% block doc -%}
  File "c:\users\ssant\drive\github\dashboard\venv_dashboard\lib\site-packages\flask_bootstrap\templates\bootstrap\base.html", line 4, in block "doc"
    {%- block html %}
  File "c:\users\ssant\drive\github\dashboard\venv_dashboard\lib\site-packages\flask_bootstrap\templates\bootstrap\base.html", line 20, in block "html"
    {% block body -%}
  File "c:\users\ssant\drive\github\dashboard\venv_dashboard\lib\site-packages\flask_bootstrap\templates\bootstrap\base.html", line 21, in block "body"
    {% block navbar %}
  File "C:\Users\ssant\drive\github\dashboard\app\templates\base.html", line 27, in block "navbar"
    {{ g.search_form.q(size=20, class='form-control', placeholder=g.search_form.q.label.text) }}
  File "c:\users\ssant\drive\github\dashboard\venv_dashboard\lib\site-packages\wtforms\fields\core.py", line 153, in __call__
    return self.meta.render_field(self, kwargs)
  File "c:\users\ssant\drive\github\dashboard\venv_dashboard\lib\site-packages\wtforms\meta.py", line 56, in render_field
    return field.widget(field, **render_kw)
  File "c:\users\ssant\drive\github\dashboard\venv_dashboard\lib\site-packages\wtforms\widgets\core.py", line 164, in __call__
    return HTMLString('<input %s>' % self.html_params(name=field.name, **kwargs))
  File "c:\users\ssant\drive\github\dashboard\venv_dashboard\lib\site-packages\wtforms\widgets\core.py", line 53, in html_params
    params.append('%s="%s"' % (text_type(k), escape(text_type(v), quote=True)))
  File "c:\users\ssant\drive\github\dashboard\venv_dashboard\lib\site-packages\flask_babel\speaklater.py", line 23, in __str__
    return text_type(self._func(*self._args, **self._kwargs))
  File "c:\users\ssant\drive\github\dashboard\venv_dashboard\lib\site-packages\flask_babel\__init__.py", line 552, in gettext
    t = get_translations()
  File "c:\users\ssant\drive\github\dashboard\venv_dashboard\lib\site-packages\flask_babel\__init__.py", line 223, in get_translations
    babel = current_app.extensions['babel']
KeyError: 'babel'
2020-02-17 22:06:29,701 INFO: Dashboard startup [in C:\Users\ssant\drive\github\dashboard\app\__init__.py:73]
2020-02-17 22:20:04,712 INFO: Dashboard startup [in C:\Users\ssant\drive\github\dashboard\app\__init__.py:73]
2020-02-17 22:21:44,073 INFO: Dashboard startup [in C:\Users\ssant\drive\github\dashboard\app\__init__.py:73]
2020-02-17 23:12:38,729 INFO: Dashboard startup [in C:\Users\ssant\drive\github\dashboard\app\__init__.py:73]
2020-02-17 23:13:13,460 INFO: Dashboard startup [in C:\Users\ssant\drive\github\dashboard\app\__init__.py:73]
2020-02-17 23:13:33,700 INFO: Dashboard startup [in C:\Users\ssant\drive\github\dashboard\app\__init__.py:73]
2020-02-17 23:13:34,610 ERROR: Exception on / [GET] [in c:\users\ssant\drive\github\dashboard\venv_dashboard\lib\site-packages\flask\app.py:1761]
Traceback (most recent call last):
  File "c:\users\ssant\drive\github\dashboard\venv_dashboard\lib\site-packages\flask\app.py", line 2292, in wsgi_app
    response = self.full_dispatch_request()
  File "c:\users\ssant\drive\github\dashboard\venv_dashboard\lib\site-packages\flask\app.py", line 1815, in full_dispatch_request
    rv = self.handle_user_exception(e)
  File "c:\users\ssant\drive\github\dashboard\venv_dashboard\lib\site-packages\flask\app.py", line 1718, in handle_user_exception
    reraise(exc_type, exc_value, tb)
  File "c:\users\ssant\drive\github\dashboard\venv_dashboard\lib\site-packages\flask\_compat.py", line 35, in reraise
    raise value
  File "c:\users\ssant\drive\github\dashboard\venv_dashboard\lib\site-packages\flask\app.py", line 1813, in full_dispatch_request
    rv = self.dispatch_request()
  File "c:\users\ssant\drive\github\dashboard\venv_dashboard\lib\site-packages\flask\app.py", line 1799, in dispatch_request
    return self.view_functions[rule.endpoint](**req.view_args)
  File "C:\Users\ssant\drive\github\dashboard\app\main\routes.py", line 30, in index
    projects = current_user.followed_projects().paginate(
  File "c:\users\ssant\drive\github\dashboard\venv_dashboard\lib\site-packages\werkzeug\local.py", line 347, in __getattr__
    return getattr(self._get_current_object(), name)
AttributeError: 'AnonymousUserMixin' object has no attribute 'followed_projects'
2020-02-17 23:14:49,080 INFO: Dashboard startup [in C:\Users\ssant\drive\github\dashboard\app\__init__.py:73]
2020-02-18 06:38:26,952 INFO: Dashboard startup [in C:\Users\ssant\drive\github\dashboard\app\__init__.py:73]
2020-02-18 06:44:29,373 INFO: Dashboard startup [in C:\Users\ssant\drive\github\dashboard\app\__init__.py:73]
2020-02-18 06:51:53,116 INFO: Dashboard startup [in C:\Users\ssant\drive\github\dashboard\app\__init__.py:73]
